- /home/student/Testarea/250416_NICER_Flux/nicer_rand_obs:: 'yVals'
- /home/student/Testarea/250416_NICER_Flux/nicer_rand_obs:: Traceback (most recent call last):
  File "/home/student/miniconda3/lib/python3.12/site-packages/pandas/core/indexes/base.py", line 3805, in get_loc
    return self._engine.get_loc(casted_key)
           ^^^^^^^^^^^^^^^^^^^^^^^^^^^^^^^^
  File "index.pyx", line 167, in pandas._libs.index.IndexEngine.get_loc
  File "index.pyx", line 196, in pandas._libs.index.IndexEngine.get_loc
  File "pandas/_libs/hashtable_class_helper.pxi", line 7081, in pandas._libs.hashtable.PyObjectHashTable.get_item
  File "pandas/_libs/hashtable_class_helper.pxi", line 7089, in pandas._libs.hashtable.PyObjectHashTable.get_item
KeyError: 'yVals'

The above exception was the direct cause of the following exception:

Traceback (most recent call last):
  File "/home/student/GitHome/nicer-xspec/src/plot_spec.py", line 86, in <module>
    plot_spectrum(df_spect=df_spect, fpath=fpath, mname=m, df_ratio=df_ratio)
  File "/home/student/GitHome/nicer-xspec/src/plot_spec.py", line 33, in plot_spectrum
    x1, y1, y1e, mdl = df_spect["xVals"], df_spect["yVals"], df_spect["yErrs"], df_spect["modVals"]
                                          ~~~~~~~~^^^^^^^^^
  File "/home/student/miniconda3/lib/python3.12/site-packages/pandas/core/frame.py", line 4090, in __getitem__
    indexer = self.columns.get_loc(key)
              ^^^^^^^^^^^^^^^^^^^^^^^^^
  File "/home/student/miniconda3/lib/python3.12/site-packages/pandas/core/indexes/base.py", line 3812, in get_loc
    raise KeyError(key) from err
KeyError: 'yVals'

- /home/student/Testarea/250416_NICER_Flux/nicer_rand_obs:: Traceback (most recent call last):
  File "/home/student/miniconda3/lib/python3.12/site-packages/pandas/core/indexes/base.py", line 3805, in get_loc
    return self._engine.get_loc(casted_key)
           ^^^^^^^^^^^^^^^^^^^^^^^^^^^^^^^^
  File "index.pyx", line 167, in pandas._libs.index.IndexEngine.get_loc
  File "index.pyx", line 196, in pandas._libs.index.IndexEngine.get_loc
  File "pandas/_libs/hashtable_class_helper.pxi", line 7081, in pandas._libs.hashtable.PyObjectHashTable.get_item
  File "pandas/_libs/hashtable_class_helper.pxi", line 7089, in pandas._libs.hashtable.PyObjectHashTable.get_item
KeyError: 'yVals'

The above exception was the direct cause of the following exception:

Traceback (most recent call last):
  File "/home/student/GitHome/nicer-xspec/src/plot_spec.py", line 86, in <module>
    plot_spectrum(df_spect=df_spect, fpath=fpath, mname=m, df_ratio=df_ratio)
  File "/home/student/GitHome/nicer-xspec/src/plot_spec.py", line 33, in plot_spectrum
    x1, y1, y1e, mdl = df_spect["xVals"], df_spect["yVals"], df_spect["yErrs"], df_spect["modVals"]
                                          ~~~~~~~~^^^^^^^^^
  File "/home/student/miniconda3/lib/python3.12/site-packages/pandas/core/frame.py", line 4090, in __getitem__
    indexer = self.columns.get_loc(key)
              ^^^^^^^^^^^^^^^^^^^^^^^^^
  File "/home/student/miniconda3/lib/python3.12/site-packages/pandas/core/indexes/base.py", line 3812, in get_loc
    raise KeyError(key) from err
KeyError: 'yVals'

- /home/student/Testarea/250416_NICER_Flux/nicer_rand_obs:: Traceback (most recent call last):
  File "/home/student/miniconda3/lib/python3.12/site-packages/pandas/core/indexes/base.py", line 3805, in get_loc
    return self._engine.get_loc(casted_key)
           ^^^^^^^^^^^^^^^^^^^^^^^^^^^^^^^^
  File "index.pyx", line 167, in pandas._libs.index.IndexEngine.get_loc
  File "index.pyx", line 196, in pandas._libs.index.IndexEngine.get_loc
  File "pandas/_libs/hashtable_class_helper.pxi", line 7081, in pandas._libs.hashtable.PyObjectHashTable.get_item
  File "pandas/_libs/hashtable_class_helper.pxi", line 7089, in pandas._libs.hashtable.PyObjectHashTable.get_item
KeyError: 'yVals'

The above exception was the direct cause of the following exception:

Traceback (most recent call last):
  File "/home/student/GitHome/nicer-xspec/src/plot_spec.py", line 88, in <module>
    plot_spectrum(df_spect=df_spect, fpath=fpath, mname=m, df_ratio=df_ratio)
  File "/home/student/GitHome/nicer-xspec/src/plot_spec.py", line 33, in plot_spectrum
    x1, y1, y1e, mdl = df_spect["xVals"], df_spect["yVals"], df_spect["yErrs"], df_spect["modVals"]
                                          ~~~~~~~~^^^^^^^^^
  File "/home/student/miniconda3/lib/python3.12/site-packages/pandas/core/frame.py", line 4090, in __getitem__
    indexer = self.columns.get_loc(key)
              ^^^^^^^^^^^^^^^^^^^^^^^^^
  File "/home/student/miniconda3/lib/python3.12/site-packages/pandas/core/indexes/base.py", line 3812, in get_loc
    raise KeyError(key) from err
KeyError: 'yVals'

